Workbook

Sheet Einstellungen
A1: 📊 Haushaltsbuch – Einstellungen
A3: Jahr: | B3: 2026 | C3: ← Hier das Jahr ändern (z.B. 2027) – alle Blätter passen sich automatisch an
A5: Kategorien & Unterkategorien
A6: Kategorie | B6: Unterkategorien
A7: Wohnen | B7: Miete | Strom/Gas | Internet | Nebenkosten | Sonstiges
A8: Lebensmittel | B8: Supermarkt | Drogerie | Sonstiges
A9: Transport | B9: Tanken | ÖPNV | Wartung/Reparatur | Sonstiges
A10: Freizeit | B10: Kino/Events | Hobbys | Urlaub | Sonstiges
A11: Gesundheit | B11: Arzt/Apotheke | Fitness/Sport | Medikamente | Sonstiges
A12: Kleidung | B12: Kleidung | Schuhe | Accessoires | Sonstiges
A13: Restaurant | B13: Restaurant | Café | Lieferservice | Sonstiges
A14: Versicherungen | B14: Krankenversicherung | KFZ-Versicherung | Streaming/Abos | Sonstiges
A15: Sparen | B15: Tagesgeld/Sparen | Aktien/ETF | Altersvorsorge | Sonstiges
A18: Hinweise zur Bedienung
A19: 1. Trage oben das gewünschte Jahr ein – Datum & Kalender in allen Monatsblättern passen sich automatisch an.
A20: 2. SCHNELLEINGABE: Trage den Tagesbetrag direkt in die passende Kategorie-Spalte ein (Zeilen 5–35).
A21: 3. DETAIL-LOG: Für einzelne Buchungen mit Beschreibung & Unterkategorie (ab Zeile 42).
A22: 4. Tipp: Nutze die Schnelleingabe für schnelle Tageseinträge und den Detail-Log für detaillierte Auswertungen.
A23: 5. Die Jahresübersicht berechnet sich automatisch aus den Monatssummen (Schnelleingabe).
A24: 6. Die Detail-Log-Auswertung im zweiten Teil der Jahresübersicht zeigt Ausgaben nach Unterkategorien.

Sheet Jahresübersicht
A1: =TEXT(Einstellungen!$B$3,"0") & " – Jahresübersicht aller Ausgaben" -> 2026 – Jahresübersicht aller Ausgaben
A2: SCHNELLEINGABE – Monatliche Kategorie-Summen
A3: Kategorie | B3: Unterkategorie | C3: Jan | D3: Feb | E3: Mär | F3: Apr | G3: Mai | H3: Jun | I3: Jul | J3: Aug | K3: Sep | L3: Okt | M3: Nov | N3: Dez | O3: GESAMT
A4: Wohnen | B4: Gesamt Schnelleingabe | C4: =Januar!C37 -> 0 | D4: =Februar!C37 -> 0 | E4: =März!C37 -> 0 | F4: =April!C37 -> 0 | G4: =Mai!C37 -> 0 | H4: =Juni!C37 -> 0 | I4: =Juli!C37 -> 0 | J4: =August!C37 -> 0 | K4: =September!C37 -> 0 | L4: =Oktober!C37 -> 0 | M4: =November!C37 -> 0 | N4: =Dezember!C37 -> 0 | O4: =SUM(C4:N4) -> 0
A5: Lebensmittel | B5: Gesamt Schnelleingabe | C5: =Januar!D37 -> 0 | D5: =Februar!D37 -> 0 | E5: =März!D37 -> 0 | F5: =April!D37 -> 0 | G5: =Mai!D37 -> 0 | H5: =Juni!D37 -> 0 | I5: =Juli!D37 -> 0 | J5: =August!D37 -> 0 | K5: =September!D37 -> 0 | L5: =Oktober!D37 -> 0 | M5: =November!D37 -> 0 | N5: =Dezember!D37 -> 0 | O5: =SUM(C5:N5) -> 0
A6: Transport | B6: Gesamt Schnelleingabe | C6: =Januar!E37 -> 0 | D6: =Februar!E37 -> 0 | E6: =März!E37 -> 0 | F6: =April!E37 -> 0 | G6: =Mai!E37 -> 0 | H6: =Juni!E37 -> 0 | I6: =Juli!E37 -> 0 | J6: =August!E37 -> 0 | K6: =September!E37 -> 0 | L6: =Oktober!E37 -> 0 | M6: =November!E37 -> 0 | N6: =Dezember!E37 -> 0 | O6: =SUM(C6:N6) -> 0
A7: Freizeit | B7: Gesamt Schnelleingabe | C7: =Januar!F37 -> 0 | D7: =Februar!F37 -> 0 | E7: =März!F37 -> 0 | F7: =April!F37 -> 0 | G7: =Mai!F37 -> 0 | H7: =Juni!F37 -> 0 | I7: =Juli!F37 -> 0 | J7: =August!F37 -> 0 | K7: =September!F37 -> 0 | L7: =Oktober!F37 -> 0 | M7: =November!F37 -> 0 | N7: =Dezember!F37 -> 0 | O7: =SUM(C7:N7) -> 0
A8: Gesundheit | B8: Gesamt Schnelleingabe | C8: =Januar!G37 -> 0 | D8: =Februar!G37 -> 0 | E8: =März!G37 -> 0 | F8: =April!G37 -> 0 | G8: =Mai!G37 -> 0 | H8: =Juni!G37 -> 0 | I8: =Juli!G37 -> 0 | J8: =August!G37 -> 0 | K8: =September!G37 -> 0 | L8: =Oktober!G37 -> 0 | M8: =November!G37 -> 0 | N8: =Dezember!G37 -> 0 | O8: =SUM(C8:N8) -> 0
A9: Kleidung | B9: Gesamt Schnelleingabe | C9: =Januar!H37 -> 0 | D9: =Februar!H37 -> 0 | E9: =März!H37 -> 0 | F9: =April!H37 -> 0 | G9: =Mai!H37 -> 0 | H9: =Juni!H37 -> 0 | I9: =Juli!H37 -> 0 | J9: =August!H37 -> 0 | K9: =September!H37 -> 0 | L9: =Oktober!H37 -> 0 | M9: =November!H37 -> 0 | N9: =Dezember!H37 -> 0 | O9: =SUM(C9:N9) -> 0
A10: Restaurant | B10: Gesamt Schnelleingabe | C10: =Januar!I37 -> 0 | D10: =Februar!I37 -> 0 | E10: =März!I37 -> 0 | F10: =April!I37 -> 0 | G10: =Mai!I37 -> 0 | H10: =Juni!I37 -> 0 | I10: =Juli!I37 -> 0 | J10: =August!I37 -> 0 | K10: =September!I37 -> 0 | L10: =Oktober!I37 -> 0 | M10: =November!I37 -> 0 | N10: =Dezember!I37 -> 0 | O10: =SUM(C10:N10) -> 0
A11: Versicherungen | B11: Gesamt Schnelleingabe | C11: =Januar!J37 -> 0 | D11: =Februar!J37 -> 0 | E11: =März!J37 -> 0 | F11: =April!J37 -> 0 | G11: =Mai!J37 -> 0 | H11: =Juni!J37 -> 0 | I11: =Juli!J37 -> 0 | J11: =August!J37 -> 0 | K11: =September!J37 -> 0 | L11: =Oktober!J37 -> 0 | M11: =November!J37 -> 0 | N11: =Dezember!J37 -> 0 | O11: =SUM(C11:N11) -> 0
A12: Sparen | B12: Gesamt Schnelleingabe | C12: =Januar!K37 -> 0 | D12: =Februar!K37 -> 0 | E12: =März!K37 -> 0 | F12: =April!K37 -> 0 | G12: =Mai!K37 -> 0 | H12: =Juni!K37 -> 0 | I12: =Juli!K37 -> 0 | J12: =August!K37 -> 0 | K12: =September!K37 -> 0 | L12: =Oktober!K37 -> 0 | M12: =November!K37 -> 0 | N12: =Dezember!K37 -> 0 | O12: =SUM(C12:N12) -> 0
A13: GESAMTAUSGABEN | C13: =SUM(C4:C12) -> 0 | D13: =SUM(D4:D12) -> 0 | E13: =SUM(E4:E12) -> 0 | F13: =SUM(F4:F12) -> 0 | G13: =SUM(G4:G12) -> 0 | H13: =SUM(H4:H12) -> 0 | I13: =SUM(I4:I12) -> 0 | J13: =SUM(J4:J12) -> 0 | ... O13: =SUM(O4:O12) -> 0
A15: DETAIL-LOG – Aufschlüsselung nach Unterkategorie
A16: Kategorie | B16: Unterkategorie | C16: Jan | D16: Feb | E16: Mär | F16: Apr | G16: Mai | H16: Jun | I16: Jul | J16: Aug | K16: Sep | L16: Okt | M16: Nov | N16: Dez | O16: GESAMT
A17: Wohnen | B17: Miete | C17: =SUMPRODUCT((Januar!$B$42:$B$91="Wohnen")*(Januar!$C$42:$C$91="Miete")*(Januar!$E$42:$E$91)) -> 0 | D17: =SUMPRODUCT((Februar!$B$42:$B$91="Wohnen")*(Februar!$C$42:$C$91="Miete")*(Februar!$E$42:$E$91)) -> 0 | E17: =SUMPRODUCT((März!$B$42:$B$91="Wohnen")*(März!$C$42:$C$91="Miete")*(März!$E$42:$E$91)) -> 0 | F17: =SUMPRODUCT((April!$B$42:$B$91="Wohnen")*(April!$C$42:$C$91="Miete")*(April!$E$42:$E$91)) -> 0 | G17: =SUMPRODUCT((Mai!$B$42:$B$91="Wohnen")*(Mai!$C$42:$C$91="Miete")*(Mai!$E$42:$E$91)) -> 0 | H17: =SUMPRODUCT((Juni!$B$42:$B$91="Wohnen")*(Juni!$C$42:$C$91="Miete")*(Juni!$E$42:$E$91)) -> 0 | I17: =SUMPRODUCT((Juli!$B$42:$B$91="Wohnen")*(Juli!$C$42:$C$91="Miete")*(Juli!$E$42:$E$91)) -> 0 | J17: =SUMPRODUCT((August!$B$42:$B$91="Wohnen")*(August!$C$42:$C$91="Miete")*(August!$E$42:$E$91)) -> 0 | K17: =SUMPRODUCT((September!$B$42:$B$91="Wohnen")*(September!$C$42:$C$91="Miete")*(September!$E$42:$E$91)) -> 0 | L17: =SUMPRODUCT((Oktober!$B$42:$B$91="Wohnen")*(Oktober!$C$42:$C$91="Miete")*(Oktober!$E$42:$E$91)) -> 0 | M17: =SUMPRODUCT((November!$B$42:$B$91="Wohnen")*(November!$C$42:$C$91="Miete")*(November!$E$42:$E$91)) -> 0 | N17: =SUMPRODUCT((Dezember!$B$42:$B$91="Wohnen")*(Dezember!$C$42:$C$91="Miete")*(Dezember!$E$42:$E$91)) -> 0 | O17: =SUM(C17:N17) -> 0
A18: Wohnen | B18: Strom/Gas | C18: =SUMPRODUCT((Januar!$B$42:$B$91="Wohnen")*(Januar!$C$42:$C$91="Strom/Gas")*(Januar!$E$42:$E$91)) -> 0 | D18: =SUMPRODUCT((Februar!$B$42:$B$91="Wohnen")*(Februar!$C$42:$C$91="Strom/Gas")*(Februar!$E$42:$E$91)) -> 0 | E18: =SUMPRODUCT((März!$B$42:$B$91="Wohnen")*(März!$C$42:$C$91="Strom/Gas")*(März!$E$42:$E$91)) -> 0 | F18: =SUMPRODUCT((April!$B$42:$B$91="Wohnen")*(April!$C$42:$C$91="Strom/Gas")*(April!$E$42:$E$91)) -> 0 | G18: =SUMPRODUCT((Mai!$B$42:$B$91="Wohnen")*(Mai!$C$42:$C$91="Strom/Gas")*(Mai!$E$42:$E$91)) -> 0 | H18: =SUMPRODUCT((Juni!$B$42:$B$91="Wohnen")*(Juni!$C$42:$C$91="Strom/Gas")*(Juni!$E$42:$E$91)) -> 0 | I18: =SUMPRODUCT((Juli!$B$42:$B$91="Wohnen")*(Juli!$C$42:$C$91="Strom/Gas")*(Juli!$E$42:$E$91)) -> 0 | J18: =SUMPRODUCT((August!$B$42:$B$91="Wohnen")*(August!$C$42:$C$91="Strom/Gas")*(August!$E$42:$E$91)) -> 0 | K18: =SUMPRODUCT((September!$B$42:$B$91="Wohnen")*(September!$C$42:$C$91="Strom/Gas")*(September!$E$42:$E$91)) -> 0 | L18: =SUMPRODUCT((Oktober!$B$42:$B$91="Wohnen")*(Oktober!$C$42:$C$91="Strom/Gas")*(Oktober!$E$42:$E$91)) -> 0 | M18: =SUMPRODUCT((November!$B$42:$B$91="Wohnen")*(November!$C$42:$C$91="Strom/Gas")*(November!$E$42:$E$91)) -> 0 | N18: =SUMPRODUCT((Dezember!$B$42:$B$91="Wohnen")*(Dezember!$C$42:$C$91="Strom/Gas")*(Dezember!$E$42:$E$91)) -> 0 | O18: =SUM(C18:N18) -> 0
A19: Wohnen | B19: Internet | C19: =SUMPRODUCT((Januar!$B$42:$B$91="Wohnen")*(Januar!$C$42:$C$91="Internet")*(Januar!$E$42:$E$91)) -> 0 | D19: =SUMPRODUCT((Februar!$B$42:$B$91="Wohnen")*(Februar!$C$42:$C$91="Internet")*(Februar!$E$42:$E$91)) -> 0 | E19: =SUMPRODUCT((März!$B$42:$B$91="Wohnen")*(März!$C$42:$C$91="Internet")*(März!$E$42:$E$91)) -> 0 | F19: =SUMPRODUCT((April!$B$42:$B$91="Wohnen")*(April!$C$42:$C$91="Internet")*(April!$E$42:$E$91)) -> 0 | G19: =SUMPRODUCT((Mai!$B$42:$B$91="Wohnen")*(Mai!$C$42:$C$91="Internet")*(Mai!$E$42:$E$91)) -> 0 | H19: =SUMPRODUCT((Juni!$B$42:$B$91="Wohnen")*(Juni!$C$42:$C$91="Internet")*(Juni!$E$42:$E$91)) -> 0 | I19: =SUMPRODUCT((Juli!$B$42:$B$91="Wohnen")*(Juli!$C$42:$C$91="Internet")*(Juli!$E$42:$E$91)) -> 0 | J19: =SUMPRODUCT((August!$B$42:$B$91="Wohnen")*(August!$C$42:$C$91="Internet")*(August!$E$42:$E$91)) -> 0 | K19: =SUMPRODUCT((September!$B$42:$B$91="Wohnen")*(September!$C$42:$C$91="Internet")*(September!$E$42:$E$91)) -> 0 | L19: =SUMPRODUCT((Oktober!$B$42:$B$91="Wohnen")*(Oktober!$C$42:$C$91="Internet")*(Oktober!$E$42:$E$91)) -> 0 | M19: =SUMPRODUCT((November!$B$42:$B$91="Wohnen")*(November!$C$42:$C$91="Internet")*(November!$E$42:$E$91)) -> 0 | N19: =SUMPRODUCT((Dezember!$B$42:$B$91="Wohnen")*(Dezember!$C$42:$C$91="Internet")*(Dezember!$E$42:$E$91)) -> 0 | O19: =SUM(C19:N19) -> 0
A20: Wohnen | B20: Nebenkosten | C20: =SUMPRODUCT((Januar!$B$42:$B$91="Wohnen")*(Januar!$C$42:$C$91="Nebenkosten")*(Januar!$E$42:$E$91)) -> 0 | D20: =SUMPRODUCT((Februar!$B$42:$B$91="Wohnen")*(Februar!$C$42:$C$91="Nebenkosten")*(Februar!$E$42:$E$91)) -> 0 | E20: =SUMPRODUCT((März!$B$42:$B$91="Wohnen")*(März!$C$42:$C$91="Nebenkosten")*(März!$E$42:$E$91)) -> 0 | F20: =SUMPRODUCT((April!$B$42:$B$91="Wohnen")*(April!$C$42:$C$91="Nebenkosten")*(April!$E$42:$E$91)) -> 0 | G20: =SUMPRODUCT((Mai!$B$42:$B$91="Wohnen")*(Mai!$C$42:$C$91="Nebenkosten")*(Mai!$E$42:$E$91)) -> 0 | H20: =SUMPRODUCT((Juni!$B$42:$B$91="Wohnen")*(Juni!$C$42:$C$91="Nebenkosten")*(Juni!$E$42:$E$91)) -> 0 | I20: =SUMPRODUCT((Juli!$B$42:$B$91="Wohnen")*(Juli!$C$42:$C$91="Nebenkosten")*(Juli!$E$42:$E$91)) -> 0 | J20: =SUMPRODUCT((August!$B$42:$B$91="Wohnen")*(August!$C$42:$C$91="Nebenkosten")*(August!$E$42:$E$91)) -> 0 | K20: =SUMPRODUCT((September!$B$42:$B$91="Wohnen")*(September!$C$42:$C$91="Nebenkosten")*(September!$E$42:$E$91)) -> 0 | L20: =SUMPRODUCT((Oktober!$B$42:$B$91="Wohnen")*(Oktober!$C$42:$C$91="Nebenkosten")*(Oktober!$E$42:$E$91)) -> 0 | M20: =SUMPRODUCT((November!$B$42:$B$91="Wohnen")*(November!$C$42:$C$91="Nebenkosten")*(November!$E$42:$E$91)) -> 0 | N20: =SUMPRODUCT((Dezember!$B$42:$B$91="Wohnen")*(Dezember!$C$42:$C$91="Nebenkosten")*(Dezember!$E$42:$E$91)) -> 0 | O20: =SUM(C20:N20) -> 0
A21: Wohnen | B21: Sonstiges | C21: =SUMPRODUCT((Januar!$B$42:$B$91="Wohnen")*(Januar!$C$42:$C$91="Sonstiges")*(Januar!$E$42:$E$91)) -> 0 | D21: =SUMPRODUCT((Februar!$B$42:$B$91="Wohnen")*(Februar!$C$42:$C$91="Sonstiges")*(Februar!$E$42:$E$91)) -> 0 | E21: =SUMPRODUCT((März!$B$42:$B$91="Wohnen")*(März!$C$42:$C$91="Sonstiges")*(März!$E$42:$E$91)) -> 0 | F21: =SUMPRODUCT((April!$B$42:$B$91="Wohnen")*(April!$C$42:$C$91="Sonstiges")*(April!$E$42:$E$91)) -> 0 | G21: =SUMPRODUCT((Mai!$B$42:$B$91="Wohnen")*(Mai!$C$42:$C$91="Sonstiges")*(Mai!$E$42:$E$91)) -> 0 | H21: =SUMPRODUCT((Juni!$B$42:$B$91="Wohnen")*(Juni!$C$42:$C$91="Sonstiges")*(Juni!$E$42:$E$91)) -> 0 | I21: =SUMPRODUCT((Juli!$B$42:$B$91="Wohnen")*(Juli!$C$42:$C$91="Sonstiges")*(Juli!$E$42:$E$91)) -> 0 | J21: =SUMPRODUCT((August!$B$42:$B$91="Wohnen")*(August!$C$42:$C$91="Sonstiges")*(August!$E$42:$E$91)) -> 0 | K21: =SUMPRODUCT((September!$B$42:$B$91="Wohnen")*(September!$C$42:$C$91="Sonstiges")*(September!$E$42:$E$91)) -> 0 | L21: =SUMPRODUCT((Oktober!$B$42:$B$91="Wohnen")*(Oktober!$C$42:$C$91="Sonstiges")*(Oktober!$E$42:$E$91)) -> 0 | M21: =SUMPRODUCT((November!$B$42:$B$91="Wohnen")*(November!$C$42:$C$91="Sonstiges")*(November!$E$42:$E$91)) -> 0 | N21: =SUMPRODUCT((Dezember!$B$42:$B$91="Wohnen")*(Dezember!$C$42:$C$91="Sonstiges")*(Dezember!$E$42:$E$91)) -> 0 | O21: =SUM(C21:N21) -> 0
A22: Wohnen | B22: → Gesamt | C22: =SUM(C17:C21) -> 0 | D22: =SUM(D17:D21) -> 0 | E22: =SUM(E17:E21) -> 0 | F22: =SUM(F17:F21) -> 0 | G22: =SUM(G17:G21) -> 0 | H22: =SUM(H17:H21) -> 0 | I22: =SUM(I17:I21) -> 0 | J22: =SUM(J17:J21) -> 0 | ... O22: =SUM(O17:O21) -> 0
A24: Lebensmittel | B24: Supermarkt | C24: =SUMPRODUCT((Januar!$B$42:$B$91="Lebensmittel")*(Januar!$C$42:$C$91="Supermarkt")*(Januar!$E$42:$E$91)) -> 0 | D24: =SUMPRODUCT((Februar!$B$42:$B$91="Lebensmittel")*(Februar!$C$42:$C$91="Supermarkt")*(Februar!$E$42:$E$91)) -> 0 | E24: =SUMPRODUCT((März!$B$42:$B$91="Lebensmittel")*(März!$C$42:$C$91="Supermarkt")*(März!$E$42:$E$91)) -> 0 | F24: =SUMPRODUCT((April!$B$42:$B$91="Lebensmittel")*(April!$C$42:$C$91="Supermarkt")*(April!$E$42:$E$91)) -> 0 | G24: =SUMPRODUCT((Mai!$B$42:$B$91="Lebensmittel")*(Mai!$C$42:$C$91="Supermarkt")*(Mai!$E$42:$E$91)) -> 0 | H24: =SUMPRODUCT((Juni!$B$42:$B$91="Lebensmittel")*(Juni!$C$42:$C$91="Supermarkt")*(Juni!$E$42:$E$91)) -> 0 | I24: =SUMPRODUCT((Juli!$B$42:$B$91="Lebensmittel")*(Juli!$C$42:$C$91="Supermarkt")*(Juli!$E$42:$E$91)) -> 0 | J24: =SUMPRODUCT((August!$B$42:$B$91="Lebensmittel")*(August!$C$42:$C$91="Supermarkt")*(August!$E$42:$E$91)) -> 0 | K24: =SUMPRODUCT((September!$B$42:$B$91="Lebensmittel")*(September!$C$42:$C$91="Supermarkt")*(September!$E$42:$E$91)) -> 0 | L24: =SUMPRODUCT((Oktober!$B$42:$B$91="Lebensmittel")*(Oktober!$C$42:$C$91="Supermarkt")*(Oktober!$E$42:$E$91)) -> 0 | M24: =SUMPRODUCT((November!$B$42:$B$91="Lebensmittel")*(November!$C$42:$C$91="Supermarkt")*(November!$E$42:$E$91)) -> 0 | N24: =SUMPRODUCT((Dezember!$B$42:$B$91="Lebensmittel")*(Dezember!$C$42:$C$91="Supermarkt")*(Dezember!$E$42:$E$91)) -> 0 | O24: =SUM(C24:N24) -> 0
A25: Lebensmittel | B25: Drogerie | C25: =SUMPRODUCT((Januar!$B$42:$B$91="Lebensmittel")*(Januar!$C$42:$C$91="Drogerie")*(Januar!$E$42:$E$91)) -> 0 | D25: =SUMPRODUCT((Februar!$B$42:$B$91="Lebensmittel")*(Februar!$C$42:$C$91="Drogerie")*(Februar!$E$42:$E$91)) -> 0 | E25: =SUMPRODUCT((März!$B$42:$B$91="Lebensmittel")*(März!$C$42:$C$91="Drogerie")*(März!$E$42:$E$91)) -> 0 | F25: =SUMPRODUCT((April!$B$42:$B$91="Lebensmittel")*(April!$C$42:$C$91="Drogerie")*(April!$E$42:$E$91)) -> 0 | G25: =SUMPRODUCT((Mai!$B$42:$B$91="Lebensmittel")*(Mai!$C$42:$C$91="Drogerie")*(Mai!$E$42:$E$91)) -> 0 | H25: =SUMPRODUCT((Juni!$B$42:$B$91="Lebensmittel")*(Juni!$C$42:$C$91="Drogerie")*(Juni!$E$42:$E$91)) -> 0 | I25: =SUMPRODUCT((Juli!$B$42:$B$91="Lebensmittel")*(Juli!$C$42:$C$91="Drogerie")*(Juli!$E$42:$E$91)) -> 0 | J25: =SUMPRODUCT((August!$B$42:$B$91="Lebensmittel")*(August!$C$42:$C$91="Drogerie")*(August!$E$42:$E$91)) -> 0 | K25: =SUMPRODUCT((September!$B$42:$B$91="Lebensmittel")*(September!$C$42:$C$91="Drogerie")*(September!$E$42:$E$91)) -> 0 | L25: =SUMPRODUCT((Oktober!$B$42:$B$91="Lebensmittel")*(Oktober!$C$42:$C$91="Drogerie")*(Oktober!$E$42:$E$91)) -> 0 | M25: =SUMPRODUCT((November!$B$42:$B$91="Lebensmittel")*(November!$C$42:$C$91="Drogerie")*(November!$E$42:$E$91)) -> 0 | N25: =SUMPRODUCT((Dezember!$B$42:$B$91="Lebensmittel")*(Dezember!$C$42:$C$91="Drogerie")*(Dezember!$E$42:$E$91)) -> 0 | O25: =SUM(C25:N25) -> 0
A26: Lebensmittel | B26: Sonstiges | C26: =SUMPRODUCT((Januar!$B$42:$B$91="Lebensmittel")*(Januar!$C$42:$C$91="Sonstiges")*(Januar!$E$42:$E$91)) -> 0 | D26: =SUMPRODUCT((Februar!$B$42:$B$91="Lebensmittel")*(Februar!$C$42:$C$91="Sonstiges")*(Februar!$E$42:$E$91)) -> 0 | E26: =SUMPRODUCT((März!$B$42:$B$91="Lebensmittel")*(März!$C$42:$C$91="Sonstiges")*(März!$E$42:$E$91)) -> 0 | F26: =SUMPRODUCT((April!$B$42:$B$91="Lebensmittel")*(April!$C$42:$C$91="Sonstiges")*(April!$E$42:$E$91)) -> 0 | G26: =SUMPRODUCT((Mai!$B$42:$B$91="Lebensmittel")*(Mai!$C$42:$C$91="Sonstiges")*(Mai!$E$42:$E$91)) -> 0 | H26: =SUMPRODUCT((Juni!$B$42:$B$91="Lebensmittel")*(Juni!$C$42:$C$91="Sonstiges")*(Juni!$E$42:$E$91)) -> 0 | I26: =SUMPRODUCT((Juli!$B$42:$B$91="Lebensmittel")*(Juli!$C$42:$C$91="Sonstiges")*(Juli!$E$42:$E$91)) -> 0 | J26: =SUMPRODUCT((August!$B$42:$B$91="Lebensmittel")*(August!$C$42:$C$91="Sonstiges")*(August!$E$42:$E$91)) -> 0 | K26: =SUMPRODUCT((September!$B$42:$B$91="Lebensmittel")*(September!$C$42:$C$91="Sonstiges")*(September!$E$42:$E$91)) -> 0 | L26: =SUMPRODUCT((Oktober!$B$42:$B$91="Lebensmittel")*(Oktober!$C$42:$C$91="Sonstiges")*(Oktober!$E$42:$E$91)) -> 0 | M26: =SUMPRODUCT((November!$B$42:$B$91="Lebensmittel")*(November!$C$42:$C$91="Sonstiges")*(November!$E$42:$E$91)) -> 0 | N26: =SUMPRODUCT((Dezember!$B$42:$B$91="Lebensmittel")*(Dezember!$C$42:$C$91="Sonstiges")*(Dezember!$E$42:$E$91)) -> 0 | O26: =SUM(C26:N26) -> 0
A27: Lebensmittel | B27: → Gesamt | C27: =SUM(C24:C26) -> 0 | D27: =SUM(D24:D26) -> 0 | E27: =SUM(E24:E26) -> 0 | F27: =SUM(F24:F26) -> 0 | G27: =SUM(G24:G26) -> 0 | H27: =SUM(H24:H26) -> 0 | I27: =SUM(I24:I26) -> 0 | J27: =SUM(J24:J26) -> 0 | ... O27: =SUM(O24:O26) -> 0
A29: Transport | B29: Tanken | C29: =SUMPRODUCT((Januar!$B$42:$B$91="Transport")*(Januar!$C$42:$C$91="Tanken")*(Januar!$E$42:$E$91)) -> 0 | D29: =SUMPRODUCT((Februar!$B$42:$B$91="Transport")*(Februar!$C$42:$C$91="Tanken")*(Februar!$E$42:$E$91)) -> 0 | E29: =SUMPRODUCT((März!$B$42:$B$91="Transport")*(März!$C$42:$C$91="Tanken")*(März!$E$42:$E$91)) -> 0 | F29: =SUMPRODUCT((April!$B$42:$B$91="Transport")*(April!$C$42:$C$91="Tanken")*(April!$E$42:$E$91)) -> 0 | G29: =SUMPRODUCT((Mai!$B$42:$B$91="Transport")*(Mai!$C$42:$C$91="Tanken")*(Mai!$E$42:$E$91)) -> 0 | H29: =SUMPRODUCT((Juni!$B$42:$B$91="Transport")*(Juni!$C$42:$C$91="Tanken")*(Juni!$E$42:$E$91)) -> 0 | I29: =SUMPRODUCT((Juli!$B$42:$B$91="Transport")*(Juli!$C$42:$C$91="Tanken")*(Juli!$E$42:$E$91)) -> 0 | J29: =SUMPRODUCT((August!$B$42:$B$91="Transport")*(August!$C$42:$C$91="Tanken")*(August!$E$42:$E$91)) -> 0 | K29: =SUMPRODUCT((September!$B$42:$B$91="Transport")*(September!$C$42:$C$91="Tanken")*(September!$E$42:$E$91)) -> 0 | L29: =SUMPRODUCT((Oktober!$B$42:$B$91="Transport")*(Oktober!$C$42:$C$91="Tanken")*(Oktober!$E$42:$E$91)) -> 0 | M29: =SUMPRODUCT((November!$B$42:$B$91="Transport")*(November!$C$42:$C$91="Tanken")*(November!$E$42:$E$91)) -> 0 | N29: =SUMPRODUCT((Dezember!$B$42:$B$91="Transport")*(Dezember!$C$42:$C$91="Tanken")*(Dezember!$E$42:$E$91)) -> 0 | O29: =SUM(C29:N29) -> 0
A30: Transport | B30: ÖPNV | C30: =SUMPRODUCT((Januar!$B$42:$B$91="Transport")*(Januar!$C$42:$C$91="ÖPNV")*(Januar!$E$42:$E$91)) -> 0 | D30: =SUMPRODUCT((Februar!$B$42:$B$91="Transport")*(Februar!$C$42:$C$91="ÖPNV")*(Februar!$E$42:$E$91)) -> 0 | E30: =SUMPRODUCT((März!$B$42:$B$91="Transport")*(März!$C$42:$C$91="ÖPNV")*(März!$E$42:$E$91)) -> 0 | F30: =SUMPRODUCT((April!$B$42:$B$91="Transport")*(April!$C$42:$C$91="ÖPNV")*(April!$E$42:$E$91)) -> 0 | G30: =SUMPRODUCT((Mai!$B$42:$B$91="Transport")*(Mai!$C$42:$C$91="ÖPNV")*(Mai!$E$42:$E$91)) -> 0 | H30: =SUMPRODUCT((Juni!$B$42:$B$91="Transport")*(Juni!$C$42:$C$91="ÖPNV")*(Juni!$E$42:$E$91)) -> 0 | I30: =SUMPRODUCT((Juli!$B$42:$B$91="Transport")*(Juli!$C$42:$C$91="ÖPNV")*(Juli!$E$42:$E$91)) -> 0 | J30: =SUMPRODUCT((August!$B$42:$B$91="Transport")*(August!$C$42:$C$91="ÖPNV")*(August!$E$42:$E$91)) -> 0 | K30: =SUMPRODUCT((September!$B$42:$B$91="Transport")*(September!$C$42:$C$91="ÖPNV")*(September!$E$42:$E$91)) -> 0 | L30: =SUMPRODUCT((Oktober!$B$42:$B$91="Transport")*(Oktober!$C$42:$C$91="ÖPNV")*(Oktober!$E$42:$E$91)) -> 0 | M30: =SUMPRODUCT((November!$B$42:$B$91="Transport")*(November!$C$42:$C$91="ÖPNV")*(November!$E$42:$E$91)) -> 0 | N30: =SUMPRODUCT((Dezember!$B$42:$B$91="Transport")*(Dezember!$C$42:$C$91="ÖPNV")*(Dezember!$E$42:$E$91)) -> 0 | O30: =SUM(C30:N30) -> 0
A31: Transport | B31: Wartung/Reparatur | C31: =SUMPRODUCT((Januar!$B$42:$B$91="Transport")*(Januar!$C$42:$C$91="Wartung/Reparatur")*(Januar!$E$42:$E$91)) -> 0 | D31: =SUMPRODUCT((Februar!$B$42:$B$91="Transport")*(Februar!$C$42:$C$91="Wartung/Reparatur")*(Februar!$E$42:$E$91)) -> 0 | E31: =SUMPRODUCT((März!$B$42:$B$91="Transport")*(März!$C$42:$C$91="Wartung/Reparatur")*(März!$E$42:$E$91)) -> 0 | F31: =SUMPRODUCT((April!$B$42:$B$91="Transport")*(April!$C$42:$C$91="Wartung/Reparatur")*(April!$E$42:$E$91)) -> 0 | G31: =SUMPRODUCT((Mai!$B$42:$B$91="Transport")*(Mai!$C$42:$C$91="Wartung/Reparatur")*(Mai!$E$42:$E$91)) -> 0 | H31: =SUMPRODUCT((Juni!$B$42:$B$91="Transport")*(Juni!$C$42:$C$91="Wartung/Reparatur")*(Juni!$E$42:$E$91)) -> 0 | I31: =SUMPRODUCT((Juli!$B$42:$B$91="Transport")*(Juli!$C$42:$C$91="Wartung/Reparatur")*(Juli!$E$42:$E$91)) -> 0 | J31: =SUMPRODUCT((August!$B$42:$B$91="Transport")*(August!$C$42:$C$91="Wartung/Reparatur")*(August!$E$42:$E$91)) -> 0 | K31: =SUMPRODUCT((September!$B$42:$B$91="Transport")*(September!$C$42:$C$91="Wartung/Reparatur")*(September!$E$42:$E$91)) -> 0 | L31: =SUMPRODUCT((Oktober!$B$42:$B$91="Transport")*(Oktober!$C$42:$C$91="Wartung/Reparatur")*(Oktober!$E$42:$E$91)) -> 0 | M31: =SUMPRODUCT((November!$B$42:$B$91="Transport")*(November!$C$42:$C$91="Wartung/Reparatur")*(November!$E$42:$E$91)) -> 0 | N31: =SUMPRODUCT((Dezember!$B$42:$B$91="Transport")*(Dezember!$C$42:$C$91="Wartung/Reparatur")*(Dezember!$E$42:$E$91)) -> 0 | O31: =SUM(C31:N31) -> 0
A32: Transport | B32: Sonstiges | C32: =SUMPRODUCT((Januar!$B$42:$B$91="Transport")*(Januar!$C$42:$C$91="Sonstiges")*(Januar!$E$42:$E$91)) -> 0 | D32: =SUMPRODUCT((Februar!$B$42:$B$91="Transport")*(Februar!$C$42:$C$91="Sonstiges")*(Februar!$E$42:$E$91)) -> 0 | E32: =SUMPRODUCT((März!$B$42:$B$91="Transport")*(März!$C$42:$C$91="Sonstiges")*(März!$E$42:$E$91)) -> 0 | F32: =SUMPRODUCT((April!$B$42:$B$91="Transport")*(April!$C$42:$C$91="Sonstiges")*(April!$E$42:$E$91)) -> 0 | G32: =SUMPRODUCT((Mai!$B$42:$B$91="Transport")*(Mai!$C$42:$C$91="Sonstiges")*(Mai!$E$42:$E$91)) -> 0 | H32: =SUMPRODUCT((Juni!$B$42:$B$91="Transport")*(Juni!$C$42:$C$91="Sonstiges")*(Juni!$E$42:$E$91)) -> 0 | I32: =SUMPRODUCT((Juli!$B$42:$B$91="Transport")*(Juli!$C$42:$C$91="Sonstiges")*(Juli!$E$42:$E$91)) -> 0 | J32: =SUMPRODUCT((August!$B$42:$B$91="Transport")*(August!$C$42:$C$91="Sonstiges")*(August!$E$42:$E$91)) -> 0 | K32: =SUMPRODUCT((September!$B$42:$B$91="Transport")*(September!$C$42:$C$91="Sonstiges")*(September!$E$42:$E$91)) -> 0 | L32: =SUMPRODUCT((Oktober!$B$42:$B$91="Transport")*(Oktober!$C$42:$C$91="Sonstiges")*(Oktober!$E$42:$E$91)) -> 0 | M32: =SUMPRODUCT((November!$B$42:$B$91="Transport")*(November!$C$42:$C$91="Sonstiges")*(November!$E$42:$E$91)) -> 0 | N32: =SUMPRODUCT((Dezember!$B$42:$B$91="Transport")*(Dezember!$C$42:$C$91="Sonstiges")*(Dezember!$E$42:$E$91)) -> 0 | O32: =SUM(C32:N32) -> 0
A33: Transport | B33: → Gesamt | C33: =SUM(C29:C32) -> 0 | D33: =SUM(D29:D32) -> 0 | E33: =SUM(E29:E32) -> 0 | F33: =SUM(F29:F32) -> 0 | G33: =SUM(G29:G32) -> 0 | H33: =SUM(H29:H32) -> 0 | I33: =SUM(I29:I32) -> 0 | J33: =SUM(J29:J32) -> 0 | ... O33: =SUM(O29:O32) -> 0
A35: Freizeit | B35: Kino/Events | C35: =SUMPRODUCT((Januar!$B$42:$B$91="Freizeit")*(Januar!$C$42:$C$91="Kino/Events")*(Januar!$E$42:$E$91)) -> 0 | D35: =SUMPRODUCT((Februar!$B$42:$B$91="Freizeit")*(Februar!$C$42:$C$91="Kino/Events")*(Februar!$E$42:$E$91)) -> 0 | E35: =SUMPRODUCT((März!$B$42:$B$91="Freizeit")*(März!$C$42:$C$91="Kino/Events")*(März!$E$42:$E$91)) -> 0 | F35: =SUMPRODUCT((April!$B$42:$B$91="Freizeit")*(April!$C$42:$C$91="Kino/Events")*(April!$E$42:$E$91)) -> 0 | G35: =SUMPRODUCT((Mai!$B$42:$B$91="Freizeit")*(Mai!$C$42:$C$91="Kino/Events")*(Mai!$E$42:$E$91)) -> 0 | H35: =SUMPRODUCT((Juni!$B$42:$B$91="Freizeit")*(Juni!$C$42:$C$91="Kino/Events")*(Juni!$E$42:$E$91)) -> 0 | I35: =SUMPRODUCT((Juli!$B$42:$B$91="Freizeit")*(Juli!$C$42:$C$91="Kino/Events")*(Juli!$E$42:$E$91)) -> 0 | J35: =SUMPRODUCT((August!$B$42:$B$91="Freizeit")*(August!$C$42:$C$91="Kino/Events")*(August!$E$42:$E$91)) -> 0 | K35: =SUMPRODUCT((September!$B$42:$B$91="Freizeit")*(September!$C$42:$C$91="Kino/Events")*(September!$E$42:$E$91)) -> 0 | L35: =SUMPRODUCT((Oktober!$B$42:$B$91="Freizeit")*(Oktober!$C$42:$C$91="Kino/Events")*(Oktober!$E$42:$E$91)) -> 0 | M35: =SUMPRODUCT((November!$B$42:$B$91="Freizeit")*(November!$C$42:$C$91="Kino/Events")*(November!$E$42:$E$91)) -> 0 | N35: =SUMPRODUCT((Dezember!$B$42:$B$91="Freizeit")*(Dezember!$C$42:$C$91="Kino/Events")*(Dezember!$E$42:$E$91)) -> 0 | O35: =SUM(C35:N35) -> 0
A36: Freizeit | B36: Hobbys | C36: =SUMPRODUCT((Januar!$B$42:$B$91="Freizeit")*(Januar!$C$42:$C$91="Hobbys")*(Januar!$E$42:$E$91)) -> 0 | D36: =SUMPRODUCT((Februar!$B$42:$B$91="Freizeit")*(Februar!$C$42:$C$91="Hobbys")*(Februar!$E$42:$E$91)) -> 0 | E36: =SUMPRODUCT((März!$B$42:$B$91="Freizeit")*(März!$C$42:$C$91="Hobbys")*(März!$E$42:$E$91)) -> 0 | F36: =SUMPRODUCT((April!$B$42:$B$91="Freizeit")*(April!$C$42:$C$91="Hobbys")*(April!$E$42:$E$91)) -> 0 | G36: =SUMPRODUCT((Mai!$B$42:$B$91="Freizeit")*(Mai!$C$42:$C$91="Hobbys")*(Mai!$E$42:$E$91)) -> 0 | H36: =SUMPRODUCT((Juni!$B$42:$B$91="Freizeit")*(Juni!$C$42:$C$91="Hobbys")*(Juni!$E$42:$E$91)) -> 0 | I36: =SUMPRODUCT((Juli!$B$42:$B$91="Freizeit")*(Juli!$C$42:$C$91="Hobbys")*(Juli!$E$42:$E$91)) -> 0 | J36: =SUMPRODUCT((August!$B$42:$B$91="Freizeit")*(August!$C$42:$C$91="Hobbys")*(August!$E$42:$E$91)) -> 0 | K36: =SUMPRODUCT((September!$B$42:$B$91="Freizeit")*(September!$C$42:$C$91="Hobbys")*(September!$E$42:$E$91)) -> 0 | L36: =SUMPRODUCT((Oktober!$B$42:$B$91="Freizeit")*(Oktober!$C$42:$C$91="Hobbys")*(Oktober!$E$42:$E$91)) -> 0 | M36: =SUMPRODUCT((November!$B$42:$B$91="Freizeit")*(November!$C$42:$C$91="Hobbys")*(November!$E$42:$E$91)) -> 0 | N36: =SUMPRODUCT((Dezember!$B$42:$B$91="Freizeit")*(Dezember!$C$42:$C$91="Hobbys")*(Dezember!$E$42:$E$91)) -> 0 | O36: =SUM(C36:N36) -> 0
A37: Freizeit | B37: Urlaub | C37: =SUMPRODUCT((Januar!$B$42:$B$91="Freizeit")*(Januar!$C$42:$C$91="Urlaub")*(Januar!$E$42:$E$91)) -> 0 | D37: =SUMPRODUCT((Februar!$B$42:$B$91="Freizeit")*(Februar!$C$42:$C$91="Urlaub")*(Februar!$E$42:$E$91)) -> 0 | E37: =SUMPRODUCT((März!$B$42:$B$91="Freizeit")*(März!$C$42:$C$91="Urlaub")*(März!$E$42:$E$91)) -> 0 | F37: =SUMPRODUCT((April!$B$42:$B$91="Freizeit")*(April!$C$42:$C$91="Urlaub")*(April!$E$42:$E$91)) -> 0 | G37: =SUMPRODUCT((Mai!$B$42:$B$91="Freizeit")*(Mai!$C$42:$C$91="Urlaub")*(Mai!$E$42:$E$91)) -> 0 | H37: =SUMPRODUCT((Juni!$B$42:$B$91="Freizeit")*(Juni!$C$42:$C$91="Urlaub")*(Juni!$E$42:$E$91)) -> 0 | I37: =SUMPRODUCT((Juli!$B$42:$B$91="Freizeit")*(Juli!$C$42:$C$91="Urlaub")*(Juli!$E$42:$E$91)) -> 0 | J37: =SUMPRODUCT((August!$B$42:$B$91="Freizeit")*(August!$C$42:$C$91="Urlaub")*(August!$E$42:$E$91)) -> 0 | K37: =SUMPRODUCT((September!$B$42:$B$91="Freizeit")*(September!$C$42:$C$91="Urlaub")*(September!$E$42:$E$91)) -> 0 | L37: =SUMPRODUCT((Oktober!$B$42:$B$91="Freizeit")*(Oktober!$C$42:$C$91="Urlaub")*(Oktober!$E$42:$E$91)) -> 0 | M37: =SUMPRODUCT((November!$B$42:$B$91="Freizeit")*(November!$C$42:$C$91="Urlaub")*(November!$E$42:$E$91)) -> 0 | N37: =SUMPRODUCT((Dezember!$B$42:$B$91="Freizeit")*(Dezember!$C$42:$C$91="Urlaub")*(Dezember!$E$42:$E$91)) -> 0 | O37: =SUM(C37:N37) -> 0
A38: Freizeit | B38: Sonstiges | C38: =SUMPRODUCT((Januar!$B$42:$B$91="Freizeit")*(Januar!$C$42:$C$91="Sonstiges")*(Januar!$E$42:$E$91)) -> 0 | D38: =SUMPRODUCT((Februar!$B$42:$B$91="Freizeit")*(Februar!$C$42:$C$91="Sonstiges")*(Februar!$E$42:$E$91)) -> 0 | E38: =SUMPRODUCT((März!$B$42:$B$91="Freizeit")*(März!$C$42:$C$91="Sonstiges")*(März!$E$42:$E$91)) -> 0 | F38: =SUMPRODUCT((April!$B$42:$B$91="Freizeit")*(April!$C$42:$C$91="Sonstiges")*(April!$E$42:$E$91)) -> 0 | G38: =SUMPRODUCT((Mai!$B$42:$B$91="Freizeit")*(Mai!$C$42:$C$91="Sonstiges")*(Mai!$E$42:$E$91)) -> 0 | H38: =SUMPRODUCT((Juni!$B$42:$B$91="Freizeit")*(Juni!$C$42:$C$91="Sonstiges")*(Juni!$E$42:$E$91)) -> 0 | I38: =SUMPRODUCT((Juli!$B$42:$B$91="Freizeit")*(Juli!$C$42:$C$91="Sonstiges")*(Juli!$E$42:$E$91)) -> 0 | J38: =SUMPRODUCT((August!$B$42:$B$91="Freizeit")*(August!$C$42:$C$91="Sonstiges")*(August!$E$42:$E$91)) -> 0 | K38: =SUMPRODUCT((September!$B$42:$B$91="Freizeit")*(September!$C$42:$C$91="Sonstiges")*(September!$E$42:$E$91)) -> 0 | L38: =SUMPRODUCT((Oktober!$B$42:$B$91="Freizeit")*(Oktober!$C$42:$C$91="Sonstiges")*(Oktober!$E$42:$E$91)) -> 0 | M38: =SUMPRODUCT((November!$B$42:$B$91="Freizeit")*(November!$C$42:$C$91="Sonstiges")*(November!$E$42:$E$91)) -> 0 | N38: =SUMPRODUCT((Dezember!$B$42:$B$91="Freizeit")*(Dezember!$C$42:$C$91="Sonstiges")*(Dezember!$E$42:$E$91)) -> 0 | O38: =SUM(C38:N38) -> 0
A39: Freizeit | B39: → Gesamt | C39: =SUM(C35:C38) -> 0 | D39: =SUM(D35:D38) -> 0 | E39: =SUM(E35:E38) -> 0 | F39: =SUM(F35:F38) -> 0 | G39: =SUM(G35:G38) -> 0 | H39: =SUM(H35:H38) -> 0 | I39: =SUM(I35:I38) -> 0 | J39: =SUM(J35:J38) -> 0 | ... O39: =SUM(O35:O38) -> 0
A41: Gesundheit | B41: Arzt/Apotheke | C41: =SUMPRODUCT((Januar!$B$42:$B$91="Gesundheit")*(Januar!$C$42:$C$91="Arzt/Apotheke")*(Januar!$E$42:$E$91)) -> 0 | D41: =SUMPRODUCT((Februar!$B$42:$B$91="Gesundheit")*(Februar!$C$42:$C$91="Arzt/Apotheke")*(Februar!$E$42:$E$91)) -> 0 | E41: =SUMPRODUCT((März!$B$42:$B$91="Gesundheit")*(März!$C$42:$C$91="Arzt/Apotheke")*(März!$E$42:$E$91)) -> 0 | F41: =SUMPRODUCT((April!$B$42:$B$91="Gesundheit")*(April!$C$42:$C$91="Arzt/Apotheke")*(April!$E$42:$E$91)) -> 0 | G41: =SUMPRODUCT((Mai!$B$42:$B$91="Gesundheit")*(Mai!$C$42:$C$91="Arzt/Apotheke")*(Mai!$E$42:$E$91)) -> 0 | H41: =SUMPRODUCT((Juni!$B$42:$B$91="Gesundheit")*(Juni!$C$42:$C$91="Arzt/Apotheke")*(Juni!$E$42:$E$91)) -> 0 | I41: =SUMPRODUCT((Juli!$B$42:$B$91="Gesundheit")*(Juli!$C$42:$C$91="Arzt/Apotheke")*(Juli!$E$42:$E$91)) -> 0 | J41: =SUMPRODUCT((August!$B$42:$B$91="Gesundheit")*(August!$C$42:$C$91="Arzt/Apotheke")*(August!$E$42:$E$91)) -> 0 | K41: =SUMPRODUCT((September!$B$42:$B$91="Gesundheit")*(September!$C$42:$C$91="Arzt/Apotheke")*(September!$E$42:$E$91)) -> 0 | L41: =SUMPRODUCT((Oktober!$B$42:$B$91="Gesundheit")*(Oktober!$C$42:$C$91="Arzt/Apotheke")*(Oktober!$E$42:$E$91)) -> 0 | M41: =SUMPRODUCT((November!$B$42:$B$91="Gesundheit")*(November!$C$42:$C$91="Arzt/Apotheke")*(November!$E$42:$E$91)) -> 0 | N41: =SUMPRODUCT((Dezember!$B$42:$B$91="Gesundheit")*(Dezember!$C$42:$C$91="Arzt/Apotheke")*(Dezember!$E$42:$E$91)) -> 0 | O41: =SUM(C41:N41) -> 0
A42: Gesundheit | B42: Fitness/Sport | C42: =SUMPRODUCT((Januar!$B$42:$B$91="Gesundheit")*(Januar!$C$42:$C$91="Fitness/Sport")*(Januar!$E$42:$E$91)) -> 0 | D42: =SUMPRODUCT((Februar!$B$42:$B$91="Gesundheit")*(Februar!$C$42:$C$91="Fitness/Sport")*(Februar!$E$42:$E$91)) -> 0 | E42: =SUMPRODUCT((März!$B$42:$B$91="Gesundheit")*(März!$C$42:$C$91="Fitness/Sport")*(März!$E$42:$E$91)) -> 0 | F42: =SUMPRODUCT((April!$B$42:$B$91="Gesundheit")*(April!$C$42:$C$91="Fitness/Sport")*(April!$E$42:$E$91)) -> 0 | G42: =SUMPRODUCT((Mai!$B$42:$B$91="Gesundheit")*(Mai!$C$42:$C$91="Fitness/Sport")*(Mai!$E$42:$E$91)) -> 0 | H42: =SUMPRODUCT((Juni!$B$42:$B$91="Gesundheit")*(Juni!$C$42:$C$91="Fitness/Sport")*(Juni!$E$42:$E$91)) -> 0 | I42: =SUMPRODUCT((Juli!$B$42:$B$91="Gesundheit")*(Juli!$C$42:$C$91="Fitness/Sport")*(Juli!$E$42:$E$91)) -> 0 | J42: =SUMPRODUCT((August!$B$42:$B$91="Gesundheit")*(August!$C$42:$C$91="Fitness/Sport")*(August!$E$42:$E$91)) -> 0 | K42: =SUMPRODUCT((September!$B$42:$B$91="Gesundheit")*(September!$C$42:$C$91="Fitness/Sport")*(September!$E$42:$E$91)) -> 0 | L42: =SUMPRODUCT((Oktober!$B$42:$B$91="Gesundheit")*(Oktober!$C$42:$C$91="Fitness/Sport")*(Oktober!$E$42:$E$91)) -> 0 | M42: =SUMPRODUCT((November!$B$42:$B$91="Gesundheit")*(November!$C$42:$C$91="Fitness/Sport")*(November!$E$42:$E$91)) -> 0 | N42: =SUMPRODUCT((Dezember!$B$42:$B$91="Gesundheit")*(Dezember!$C$42:$C$91="Fitness/Sport")*(Dezember!$E$42:$E$91)) -> 0 | O42: =SUM(C42:N42) -> 0
A43: Gesundheit | B43: Medikamente | C43: =SUMPRODUCT((Januar!$B$42:$B$91="Gesundheit")*(Januar!$C$42:$C$91="Medikamente")*(Januar!$E$42:$E$91)) -> 0 | D43: =SUMPRODUCT((Februar!$B$42:$B$91="Gesundheit")*(Februar!$C$42:$C$91="Medikamente")*(Februar!$E$42:$E$91)) -> 0 | E43: =SUMPRODUCT((März!$B$42:$B$91="Gesundheit")*(März!$C$42:$C$91="Medikamente")*(März!$E$42:$E$91)) -> 0 | F43: =SUMPRODUCT((April!$B$42:$B$91="Gesundheit")*(April!$C$42:$C$91="Medikamente")*(April!$E$42:$E$91)) -> 0 | G43: =SUMPRODUCT((Mai!$B$42:$B$91="Gesundheit")*(Mai!$C$42:$C$91="Medikamente")*(Mai!$E$42:$E$91)) -> 0 | H43: =SUMPRODUCT((Juni!$B$42:$B$91="Gesundheit")*(Juni!$C$42:$C$91="Medikamente")*(Juni!$E$42:$E$91)) -> 0 | I43: =SUMPRODUCT((Juli!$B$42:$B$91="Gesundheit")*(Juli!$C$42:$C$91="Medikamente")*(Juli!$E$42:$E$91)) -> 0 | J43: =SUMPRODUCT((August!$B$42:$B$91="Gesundheit")*(August!$C$42:$C$91="Medikamente")*(August!$E$42:$E$91)) -> 0 | K43: =SUMPRODUCT((September!$B$42:$B$91="Gesundheit")*(September!$C$42:$C$91="Medikamente")*(September!$E$42:$E$91)) -> 0 | L43: =SUMPRODUCT((Oktober!$B$42:$B$91="Gesundheit")*(Oktober!$C$42:$C$91="Medikamente")*(Oktober!$E$42:$E$91)) -> 0 | M43: =SUMPRODUCT((November!$B$42:$B$91="Gesundheit")*(November!$C$42:$C$91="Medikamente")*(November!$E$42:$E$91)) -> 0 | N43: =SUMPRODUCT((Dezember!$B$42:$B$91="Gesundheit")*(Dezember!$C$42:$C$91="Medikamente")*(Dezember!$E$42:$E$91)) -> 0 | O43: =SUM(C43:N43) -> 0
A44: Gesundheit | B44: Sonstiges | C44: =SUMPRODUCT((Januar!$B$42:$B$91="Gesundheit")*(Januar!$C$42:$C$91="Sonstiges")*(Januar!$E$42:$E$91)) -> 0 | D44: =SUMPRODUCT((Februar!$B$42:$B$91="Gesundheit")*(Februar!$C$42:$C$91="Sonstiges")*(Februar!$E$42:$E$91)) -> 0 | E44: =SUMPRODUCT((März!$B$42:$B$91="Gesundheit")*(März!$C$42:$C$91="Sonstiges")*(März!$E$42:$E$91)) -> 0 | F44: =SUMPRODUCT((April!$B$42:$B$91="Gesundheit")*(April!$C$42:$C$91="Sonstiges")*(April!$E$42:$E$91)) -> 0 | G44: =SUMPRODUCT((Mai!$B$42:$B$91="Gesundheit")*(Mai!$C$42:$C$91="Sonstiges")*(Mai!$E$42:$E$91)) -> 0 | H44: =SUMPRODUCT((Juni!$B$42:$B$91="Gesundheit")*(Juni!$C$42:$C$91="Sonstiges")*(Juni!$E$42:$E$91)) -> 0 | I44: =SUMPRODUCT((Juli!$B$42:$B$91="Gesundheit")*(Juli!$C$42:$C$91="Sonstiges")*(Juli!$E$42:$E$91)) -> 0 | J44: =SUMPRODUCT((August!$B$42:$B$91="Gesundheit")*(August!$C$42:$C$91="Sonstiges")*(August!$E$42:$E$91)) -> 0 | K44: =SUMPRODUCT((September!$B$42:$B$91="Gesundheit")*(September!$C$42:$C$91="Sonstiges")*(September!$E$42:$E$91)) -> 0 | L44: =SUMPRODUCT((Oktober!$B$42:$B$91="Gesundheit")*(Oktober!$C$42:$C$91="Sonstiges")*(Oktober!$E$42:$E$91)) -> 0 | M44: =SUMPRODUCT((November!$B$42:$B$91="Gesundheit")*(November!$C$42:$C$91="Sonstiges")*(November!$E$42:$E$91)) -> 0 | N44: =SUMPRODUCT((Dezember!$B$42:$B$91="Gesundheit")*(Dezember!$C$42:$C$91="Sonstiges")*(Dezember!$E$42:$E$91)) -> 0 | O44: =SUM(C44:N44) -> 0
A45: Gesundheit | B45: → Gesamt | C45: =SUM(C41:C44) -> 0 | D45: =SUM(D41:D44) -> 0 | E45: =SUM(E41:E44) -> 0 | F45: =SUM(F41:F44) -> 0 | G45: =SUM(G41:G44) -> 0 | H45: =SUM(H41:H44) -> 0 | I45: =SUM(I41:I44) -> 0 | J45: =SUM(J41:J44) -> 0 | ... O45: =SUM(O41:O44) -> 0
...

Sheet Januar
A1: ="Januar " & TEXT(Einstellungen!$B$3,"0") -> Januar 2026
A3: ▶ SCHNELLEINGABE – Tagesausgaben nach Kategorie
A4: Datum | B4: Tag | C4: Wohnen | D4: Lebensmittel | E4: Transport | F4: Freizeit | G4: Gesundheit | H4: Kleidung | I4: Restaurant | J4: Versicherungen | K4: Sparen | L4: Gesamt | M4: Notiz
A5: =IFERROR(IF(1<=DAY(EOMONTH(DATE(Einstellungen!$B$3,1,1),0)),DATE(Einstellungen!$B$3,1,1),""),"") -> 46023 | B5: =IF(A5="","",TEXT(A5,"TTT")) -> Do | L5: =IF(A5="","",IFERROR(SUM(C5:K5),0)) -> 0
A6: =IFERROR(IF(2<=DAY(EOMONTH(DATE(Einstellungen!$B$3,1,1),0)),DATE(Einstellungen!$B$3,1,2),""),"") -> 46024 | B6: =IF(A6="","",TEXT(A6,"TTT")) -> Fr | L6: =IF(A6="","",IFERROR(SUM(C6:K6),0)) -> 0
A7: =IFERROR(IF(3<=DAY(EOMONTH(DATE(Einstellungen!$B$3,1,1),0)),DATE(Einstellungen!$B$3,1,3),""),"") -> 46025 | B7: =IF(A7="","",TEXT(A7,"TTT")) -> Sa | L7: =IF(A7="","",IFERROR(SUM(C7:K7),0)) -> 0
A8: =IFERROR(IF(4<=DAY(EOMONTH(DATE(Einstellungen!$B$3,1,1),0)),DATE(Einstellungen!$B$3,1,4),""),"") -> 46026 | B8: =IF(A8="","",TEXT(A8,"TTT")) -> So | L8: =IF(A8="","",IFERROR(SUM(C8:K8),0)) -> 0
A9: =IFERROR(IF(5<=DAY(EOMONTH(DATE(Einstellungen!$B$3,1,1),0)),DATE(Einstellungen!$B$3,1,5),""),"") -> 46027 | B9: =IF(A9="","",TEXT(A9,"TTT")) -> Mo | L9: =IF(A9="","",IFERROR(SUM(C9:K9),0)) -> 0
A10: =IFERROR(IF(6<=DAY(EOMONTH(DATE(Einstellungen!$B$3,1,1),0)),DATE(Einstellungen!$B$3,1,6),""),"") -> 46028 | B10: =IF(A10="","",TEXT(A10,"TTT")) -> Di | L10: =IF(A10="","",IFERROR(SUM(C10:K10),0)) -> 0
A11: =IFERROR(IF(7<=DAY(EOMONTH(DATE(Einstellungen!$B$3,1,1),0)),DATE(Einstellungen!$B$3,1,7),""),"") -> 46029 | B11: =IF(A11="","",TEXT(A11,"TTT")) -> Mi | L11: =IF(A11="","",IFERROR(SUM(C11:K11),0)) -> 0
A12: =IFERROR(IF(8<=DAY(EOMONTH(DATE(Einstellungen!$B$3,1,1),0)),DATE(Einstellungen!$B$3,1,8),""),"") -> 46030 | B12: =IF(A12="","",TEXT(A12,"TTT")) -> Do | L12: =IF(A12="","",IFERROR(SUM(C12:K12),0)) -> 0
A13: =IFERROR(IF(9<=DAY(EOMONTH(DATE(Einstellungen!$B$3,1,1),0)),DATE(Einstellungen!$B$3,1,9),""),"") -> 46031 | B13: =IF(A13="","",TEXT(A13,"TTT")) -> Fr | L13: =IF(A13="","",IFERROR(SUM(C13:K13),0)) -> 0
A14: =IFERROR(IF(10<=DAY(EOMONTH(DATE(Einstellungen!$B$3,1,1),0)),DATE(Einstellungen!$B$3,1,10),""),"") -> 46032 | B14: =IF(A14="","",TEXT(A14,"TTT")) -> Sa | L14: =IF(A14="","",IFERROR(SUM(C14:K14),0)) -> 0
A15: =IFERROR(IF(11<=DAY(EOMONTH(DATE(Einstellungen!$B$3,1,1),0)),DATE(Einstellungen!$B$3,1,11),""),"") -> 46033 | B15: =IF(A15="","",TEXT(A15,"TTT")) -> So | L15: =IF(A15="","",IFERROR(SUM(C15:K15),0)) -> 0
A16: =IFERROR(IF(12<=DAY(EOMONTH(DATE(Einstellungen!$B$3,1,1),0)),DATE(Einstellungen!$B$3,1,12),""),"") -> 46034 | B16: =IF(A16="","",TEXT(A16,"TTT")) -> Mo | L16: =IF(A16="","",IFERROR(SUM(C16:K16),0)) -> 0
A17: =IFERROR(IF(13<=DAY(EOMONTH(DATE(Einstellungen!$B$3,1,1),0)),DATE(Einstellungen!$B$3,1,13),""),"") -> 46035 | B17: =IF(A17="","",TEXT(A17,"TTT")) -> Di | L17: =IF(A17="","",IFERROR(SUM(C17:K17),0)) -> 0
A18: =IFERROR(IF(14<=DAY(EOMONTH(DATE(Einstellungen!$B$3,1,1),0)),DATE(Einstellungen!$B$3,1,14),""),"") -> 46036 | B18: =IF(A18="","",TEXT(A18,"TTT")) -> Mi | L18: =IF(A18="","",IFERROR(SUM(C18:K18),0)) -> 0
A19: =IFERROR(IF(15<=DAY(EOMONTH(DATE(Einstellungen!$B$3,1,1),0)),DATE(Einstellungen!$B$3,1,15),""),"") -> 46037 | B19: =IF(A19="","",TEXT(A19,"TTT")) -> Do | L19: =IF(A19="","",IFERROR(SUM(C19:K19),0)) -> 0
A20: =IFERROR(IF(16<=DAY(EOMONTH(DATE(Einstellungen!$B$3,1,1),0)),DATE(Einstellungen!$B$3,1,16),""),"") -> 46038 | B20: =IF(A20="","",TEXT(A20,"TTT")) -> Fr | L20: =IF(A20="","",IFERROR(SUM(C20:K20),0)) -> 0
A21: =IFERROR(IF(17<=DAY(EOMONTH(DATE(Einstellungen!$B$3,1,1),0)),DATE(Einstellungen!$B$3,1,17),""),"") -> 46039 | B21: =IF(A21="","",TEXT(A21,"TTT")) -> Sa | L21: =IF(A21="","",IFERROR(SUM(C21:K21),0)) -> 0
A22: =IFERROR(IF(18<=DAY(EOMONTH(DATE(Einstellungen!$B$3,1,1),0)),DATE(Einstellungen!$B$3,1,18),""),"") -> 46040 | B22: =IF(A22="","",TEXT(A22,"TTT")) -> So | L22: =IF(A22="","",IFERROR(SUM(C22:K22),0)) -> 0
A23: =IFERROR(IF(19<=DAY(EOMONTH(DATE(Einstellungen!$B$3,1,1),0)),DATE(Einstellungen!$B$3,1,19),""),"") -> 46041 | B23: =IF(A23="","",TEXT(A23,"TTT")) -> Mo | L23: =IF(A23="","",IFERROR(SUM(C23:K23),0)) -> 0
A24: =IFERROR(IF(20<=DAY(EOMONTH(DATE(Einstellungen!$B$3,1,1),0)),DATE(Einstellungen!$B$3,1,20),""),"") -> 46042 | B24: =IF(A24="","",TEXT(A24,"TTT")) -> Di | L24: =IF(A24="","",IFERROR(SUM(C24:K24),0)) -> 0
A25: =IFERROR(IF(21<=DAY(EOMONTH(DATE(Einstellungen!$B$3,1,1),0)),DATE(Einstellungen!$B$3,1,21),""),"") -> 46043 | B25: =IF(A25="","",TEXT(A25,"TTT")) -> Mi | L25: =IF(A25="","",IFERROR(SUM(C25:K25),0)) -> 0
A26: =IFERROR(IF(22<=DAY(EOMONTH(DATE(Einstellungen!$B$3,1,1),0)),DATE(Einstellungen!$B$3,1,22),""),"") -> 46044 | B26: =IF(A26="","",TEXT(A26,"TTT")) -> Do | L26: =IF(A26="","",IFERROR(SUM(C26:K26),0)) -> 0
A27: =IFERROR(IF(23<=DAY(EOMONTH(DATE(Einstellungen!$B$3,1,1),0)),DATE(Einstellungen!$B$3,1,23),""),"") -> 46045 | B27: =IF(A27="","",TEXT(A27,"TTT")) -> Fr | L27: =IF(A27="","",IFERROR(SUM(C27:K27),0)) -> 0
A28: =IFERROR(IF(24<=DAY(EOMONTH(DATE(Einstellungen!$B$3,1,1),0)),DATE(Einstellungen!$B$3,1,24),""),"") -> 46046 | B28: =IF(A28="","",TEXT(A28,"TTT")) -> Sa | L28: =IF(A28="","",IFERROR(SUM(C28:K28),0)) -> 0
A29: =IFERROR(IF(25<=DAY(EOMONTH(DATE(Einstellungen!$B$3,1,1),0)),DATE(Einstellungen!$B$3,1,25),""),"") -> 46047 | B29: =IF(A29="","",TEXT(A29,"TTT")) -> So | L29: =IF(A29="","",IFERROR(SUM(C29:K29),0)) -> 0
A30: =IFERROR(IF(26<=DAY(EOMONTH(DATE(Einstellungen!$B$3,1,1),0)),DATE(Einstellungen!$B$3,1,26),""),"") -> 46048 | B30: =IF(A30="","",TEXT(A30,"TTT")) -> Mo | L30: =IF(A30="","",IFERROR(SUM(C30:K30),0)) -> 0
A31: =IFERROR(IF(27<=DAY(EOMONTH(DATE(Einstellungen!$B$3,1,1),0)),DATE(Einstellungen!$B$3,1,27),""),"") -> 46049 | B31: =IF(A31="","",TEXT(A31,"TTT")) -> Di | L31: =IF(A31="","",IFERROR(SUM(C31:K31),0)) -> 0
A32: =IFERROR(IF(28<=DAY(EOMONTH(DATE(Einstellungen!$B$3,1,1),0)),DATE(Einstellungen!$B$3,1,28),""),"") -> 46050 | B32: =IF(A32="","",TEXT(A32,"TTT")) -> Mi | L32: =IF(A32="","",IFERROR(SUM(C32:K32),0)) -> 0
A33: =IFERROR(IF(29<=DAY(EOMONTH(DATE(Einstellungen!$B$3,1,1),0)),DATE(Einstellungen!$B$3,1,29),""),"") -> 46051 | B33: =IF(A33="","",TEXT(A33,"TTT")) -> Do | L33: =IF(A33="","",IFERROR(SUM(C33:K33),0)) -> 0
A34: =IFERROR(IF(30<=DAY(EOMONTH(DATE(Einstellungen!$B$3,1,1),0)),DATE(Einstellungen!$B$3,1,30),""),"") -> 46052 | B34: =IF(A34="","",TEXT(A34,"TTT")) -> Fr | L34: =IF(A34="","",IFERROR(SUM(C34:K34),0)) -> 0
A35: =IFERROR(IF(31<=DAY(EOMONTH(DATE(Einstellungen!$B$3,1,1),0)),DATE(Einstellungen!$B$3,1,31),""),"") -> 46053 | B35: =IF(A35="","",TEXT(A35,"TTT")) -> Sa | L35: =IF(A35="","",IFERROR(SUM(C35:K35),0)) -> 0
A37: MONATSSUMME | C37: =SUM(C5:C35) -> 0 | D37: =SUM(D5:D35) -> 0 | E37: =SUM(E5:E35) -> 0 | F37: =SUM(F5:F35) -> 0 | G37: =SUM(G5:G35) -> 0 | H37: =SUM(H5:H35) -> 0 | I37: =SUM(I5:I35) -> 0 | J37: =SUM(J5:J35) -> 0 | K37: =SUM(K5:K35) -> 0 | L37: =SUM(C37:K37) -> 0
A40: ▶ DETAIL-LOG – Einzelbuchungen mit Kategorie & Beschreibung
A41: Datum | B41: Kategorie | C41: Unterkategorie | D41: Beschreibung | E41: Betrag
A93: GESAMT DETAIL-LOG | E93: =SUM(E42:E91) -> 0

Sheet Februar
A1: ="Februar " & TEXT(Einstellungen!$B$3,"0") -> Februar 2026
A3: ▶ SCHNELLEINGABE – Tagesausgaben nach Kategorie
A4: Datum | B4: Tag | C4: Wohnen | D4: Lebensmittel | E4: Transport | F4: Freizeit | G4: Gesundheit | H4: Kleidung | I4: Restaurant | J4: Versicherungen | K4: Sparen | L4: Gesamt | M4: Notiz
A5: =IFERROR(IF(1<=DAY(EOMONTH(DATE(Einstellungen!$B$3,2,1),0)),DATE(Einstellungen!$B$3,2,1),""),"") -> 46054 | B5: =IF(A5="","",TEXT(A5,"TTT")) -> So | L5: =IF(A5="","",IFERROR(SUM(C5:K5),0)) -> 0
A6: =IFERROR(IF(2<=DAY(EOMONTH(DATE(Einstellungen!$B$3,2,1),0)),DATE(Einstellungen!$B$3,2,2),""),"") -> 46055 | B6: =IF(A6="","",TEXT(A6,"TTT")) -> Mo | L6: =IF(A6="","",IFERROR(SUM(C6:K6),0)) -> 0
A7: =IFERROR(IF(3<=DAY(EOMONTH(DATE(Einstellungen!$B$3,2,1),0)),DATE(Einstellungen!$B$3,2,3),""),"") -> 46056 | B7: =IF(A7="","",TEXT(A7,"TTT")) -> Di | L7: =IF(A7="","",IFERROR(SUM(C7:K7),0)) -> 0
A8: =IFERROR(IF(4<=DAY(EOMONTH(DATE(Einstellungen!$B$3,2,1),0)),DATE(Einstellungen!$B$3,2,4),""),"") -> 46057 | B8: =IF(A8="","",TEXT(A8,"TTT")) -> Mi | L8: =IF(A8="","",IFERROR(SUM(C8:K8),0)) -> 0
A9: =IFERROR(IF(5<=DAY(EOMONTH(DATE(Einstellungen!$B$3,2,1),0)),DATE(Einstellungen!$B$3,2,5),""),"") -> 46058 | B9: =IF(A9="","",TEXT(A9,"TTT")) -> Do | L9: =IF(A9="","",IFERROR(SUM(C9:K9),0)) -> 0
A10: =IFERROR(IF(6<=DAY(EOMONTH(DATE(Einstellungen!$B$3,2,1),0)),DATE(Einstellungen!$B$3,2,6),""),"") -> 46059 | B10: =IF(A10="","",TEXT(A10,"TTT")) -> Fr | L10: =IF(A10="","",IFERROR(SUM(C10:K10),0)) -> 0
A11: =IFERROR(IF(7<=DAY(EOMONTH(DATE(Einstellungen!$B$3,2,1),0)),DATE(Einstellungen!$B$3,2,7),""),"") -> 46060 | B11: =IF(A11="","",TEXT(A11,"TTT")) -> Sa | L11: =IF(A11="","",IFERROR(SUM(C11:K11),0)) -> 0
A12: =IFERROR(IF(8<=DAY(EOMONTH(DATE(Einstellungen!$B$3,2,1),0)),DATE(Einstellungen!$B$3,2,8),""),"") -> 46061 | B12: =IF(A12="","",TEXT(A12,"TTT")) -> So | L12: =IF(A12="","",IFERROR(SUM(C12:K12),0)) -> 0
A13: =IFERROR(IF(9<=DAY(EOMONTH(DATE(Einstellungen!$B$3,2,1),0)),DATE(Einstellungen!$B$3,2,9),""),"") -> 46062 | B13: =IF(A13="","",TEXT(A13,"TTT")) -> Mo | L13: =IF(A13="","",IFERROR(SUM(C13:K13),0)) -> 0
A14: =IFERROR(IF(10<=DAY(EOMONTH(DATE(Einstellungen!$B$3,2,1),0)),DATE(Einstellungen!$B$3,2,10),""),"") -> 46063 | B14: =IF(A14="","",TEXT(A14,"TTT")) -> Di | L14: =IF(A14="","",IFERROR(SUM(C14:K14),0)) -> 0
A15: =IFERROR(IF(11<=DAY(EOMONTH(DATE(Einstellungen!$B$3,2,1),0)),DATE(Einstellungen!$B$3,2,11),""),"") -> 46064 | B15: =IF(A15="","",TEXT(A15,"TTT")) -> Mi | L15: =IF(A15="","",IFERROR(SUM(C15:K15),0)) -> 0
A16: =IFERROR(IF(12<=DAY(EOMONTH(DATE(Einstellungen!$B$3,2,1),0)),DATE(Einstellungen!$B$3,2,12),""),"") -> 46065 | B16: =IF(A16="","",TEXT(A16,"TTT")) -> Do | L16: =IF(A16="","",IFERROR(SUM(C16:K16),0)) -> 0
A17: =IFERROR(IF(13<=DAY(EOMONTH(DATE(Einstellungen!$B$3,2,1),0)),DATE(Einstellungen!$B$3,2,13),""),"") -> 46066 | B17: =IF(A17="","",TEXT(A17,"TTT")) -> Fr | L17: =IF(A17="","",IFERROR(SUM(C17:K17),0)) -> 0
A18: =IFERROR(IF(14<=DAY(EOMONTH(DATE(Einstellungen!$B$3,2,1),0)),DATE(Einstellungen!$B$3,2,14),""),"") -> 46067 | B18: =IF(A18="","",TEXT(A18,"TTT")) -> Sa | L18: =IF(A18="","",IFERROR(SUM(C18:K18),0)) -> 0
A19: =IFERROR(IF(15<=DAY(EOMONTH(DATE(Einstellungen!$B$3,2,1),0)),DATE(Einstellungen!$B$3,2,15),""),"") -> 46068 | B19: =IF(A19="","",TEXT(A19,"TTT")) -> So | L19: =IF(A19="","",IFERROR(SUM(C19:K19),0)) -> 0
A20: =IFERROR(IF(16<=DAY(EOMONTH(DATE(Einstellungen!$B$3,2,1),0)),DATE(Einstellungen!$B$3,2,16),""),"") -> 46069 | B20: =IF(A20="","",TEXT(A20,"TTT")) -> Mo | L20: =IF(A20="","",IFERROR(SUM(C20:K20),0)) -> 0
A21: =IFERROR(IF(17<=DAY(EOMONTH(DATE(Einstellungen!$B$3,2,1),0)),DATE(Einstellungen!$B$3,2,17),""),"") -> 46070 | B21: =IF(A21="","",TEXT(A21,"TTT")) -> Di | L21: =IF(A21="","",IFERROR(SUM(C21:K21),0)) -> 0
A22: =IFERROR(IF(18<=DAY(EOMONTH(DATE(Einstellungen!$B$3,2,1),0)),DATE(Einstellungen!$B$3,2,18),""),"") -> 46071 | B22: =IF(A22="","",TEXT(A22,"TTT")) -> Mi | L22: =IF(A22="","",IFERROR(SUM(C22:K22),0)) -> 0
A23: =IFERROR(IF(19<=DAY(EOMONTH(DATE(Einstellungen!$B$3,2,1),0)),DATE(Einstellungen!$B$3,2,19),""),"") -> 46072 | B23: =IF(A23="","",TEXT(A23,"TTT")) -> Do | L23: =IF(A23="","",IFERROR(SUM(C23:K23),0)) -> 0
A24: =IFERROR(IF(20<=DAY(EOMONTH(DATE(Einstellungen!$B$3,2,1),0)),DATE(Einstellungen!$B$3,2,20),""),"") -> 46073 | B24: =IF(A24="","",TEXT(A24,"TTT")) -> Fr | L24: =IF(A24="","",IFERROR(SUM(C24:K24),0)) -> 0
A25: =IFERROR(IF(21<=DAY(EOMONTH(DATE(Einstellungen!$B$3,2,1),0)),DATE(Einstellungen!$B$3,2,21),""),"") -> 46074 | B25: =IF(A25="","",TEXT(A25,"TTT")) -> Sa | L25: =IF(A25="","",IFERROR(SUM(C25:K25),0)) -> 0
A26: =IFERROR(IF(22<=DAY(EOMONTH(DATE(Einstellungen!$B$3,2,1),0)),DATE(Einstellungen!$B$3,2,22),""),"") -> 46075 | B26: =IF(A26="","",TEXT(A26,"TTT")) -> So | L26: =IF(A26="","",IFERROR(SUM(C26:K26),0)) -> 0
A27: =IFERROR(IF(23<=DAY(EOMONTH(DATE(Einstellungen!$B$3,2,1),0)),DATE(Einstellungen!$B$3,2,23),""),"") -> 46076 | B27: =IF(A27="","",TEXT(A27,"TTT")) -> Mo | L27: =IF(A27="","",IFERROR(SUM(C27:K27),0)) -> 0
A28: =IFERROR(IF(24<=DAY(EOMONTH(DATE(Einstellungen!$B$3,2,1),0)),DATE(Einstellungen!$B$3,2,24),""),"") -> 46077 | B28: =IF(A28="","",TEXT(A28,"TTT")) -> Di | L28: =IF(A28="","",IFERROR(SUM(C28:K28),0)) -> 0
A29: =IFERROR(IF(25<=DAY(EOMONTH(DATE(Einstellungen!$B$3,2,1),0)),DATE(Einstellungen!$B$3,2,25),""),"") -> 46078 | B29: =IF(A29="","",TEXT(A29,"TTT")) -> Mi | L29: =IF(A29="","",IFERROR(SUM(C29:K29),0)) -> 0
A30: =IFERROR(IF(26<=DAY(EOMONTH(DATE(Einstellungen!$B$3,2,1),0)),DATE(Einstellungen!$B$3,2,26),""),"") -> 46079 | B30: =IF(A30="","",TEXT(A30,"TTT")) -> Do | L30: =IF(A30="","",IFERROR(SUM(C30:K30),0)) -> 0
A31: =IFERROR(IF(27<=DAY(EOMONTH(DATE(Einstellungen!$B$3,2,1),0)),DATE(Einstellungen!$B$3,2,27),""),"") -> 46080 | B31: =IF(A31="","",TEXT(A31,"TTT")) -> Fr | L31: =IF(A31="","",IFERROR(SUM(C31:K31),0)) -> 0
A32: =IFERROR(IF(28<=DAY(EOMONTH(DATE(Einstellungen!$B$3,2,1),0)),DATE(Einstellungen!$B$3,2,28),""),"") -> 46081 | B32: =IF(A32="","",TEXT(A32,"TTT")) -> Sa | L32: =IF(A32="","",IFERROR(SUM(C32:K32),0)) -> 0
A33: =IFERROR(IF(29<=DAY(EOMONTH(DATE(Einstellungen!$B$3,2,1),0)),DATE(Einstellungen!$B$3,2,29),""),"") | B33: =IF(A33="","",TEXT(A33,"TTT")) | L33: =IF(A33="","",IFERROR(SUM(C33:K33),0))
A34: =IFERROR(IF(30<=DAY(EOMONTH(DATE(Einstellungen!$B$3,2,1),0)),DATE(Einstellungen!$B$3,2,30),""),"") | B34: =IF(A34="","",TEXT(A34,"TTT")) | L34: =IF(A34="","",IFERROR(SUM(C34:K34),0))
A35: =IFERROR(IF(31<=DAY(EOMONTH(DATE(Einstellungen!$B$3,2,1),0)),DATE(Einstellungen!$B$3,2,31),""),"") | B35: =IF(A35="","",TEXT(A35,"TTT")) | L35: =IF(A35="","",IFERROR(SUM(C35:K35),0))
A37: MONATSSUMME | C37: =SUM(C5:C35) -> 0 | D37: =SUM(D5:D35) -> 0 | E37: =SUM(E5:E35) -> 0 | F37: =SUM(F5:F35) -> 0 | G37: =SUM(G5:G35) -> 0 | H37: =SUM(H5:H35) -> 0 | I37: =SUM(I5:I35) -> 0 | J37: =SUM(J5:J35) -> 0 | K37: =SUM(K5:K35) -> 0 | L37: =SUM(C37:K37) -> 0
A40: ▶ DETAIL-LOG – Einzelbuchungen mit Kategorie & Beschreibung
A41: Datum | B41: Kategorie | C41: Unterkategorie | D41: Beschreibung | E41: Betrag
A93: GESAMT DETAIL-LOG | E93: =SUM(E42:E91) -> 0

Sheet März
A1: ="März " & TEXT(Einstellungen!$B$3,"0") -> März 2026
A3: ▶ SCHNELLEINGABE – Tagesausgaben nach Kategorie
A4: Datum | B4: Tag | C4: Wohnen | D4: Lebensmittel | E4: Transport | F4: Freizeit | G4: Gesundheit | H4: Kleidung | I4: Restaurant | J4: Versicherungen | K4: Sparen | L4: Gesamt | M4: Notiz
A5: =IFERROR(IF(1<=DAY(EOMONTH(DATE(Einstellungen!$B$3,3,1),0)),DATE(Einstellungen!$B$3,3,1),""),"") -> 46082 | B5: =IF(A5="","",TEXT(A5,"TTT")) -> So | L5: =IF(A5="","",IFERROR(SUM(C5:K5),0)) -> 0
A6: =IFERROR(IF(2<=DAY(EOMONTH(DATE(Einstellungen!$B$3,3,1),0)),DATE(Einstellungen!$B$3,3,2),""),"") -> 46083 | B6: =IF(A6="","",TEXT(A6,"TTT")) -> Mo | L6: =IF(A6="","",IFERROR(SUM(C6:K6),0)) -> 0
A7: =IFERROR(IF(3<=DAY(EOMONTH(DATE(Einstellungen!$B$3,3,1),0)),DATE(Einstellungen!$B$3,3,3),""),"") -> 46084 | B7: =IF(A7="","",TEXT(A7,"TTT")) -> Di | L7: =IF(A7="","",IFERROR(SUM(C7:K7),0)) -> 0
A8: =IFERROR(IF(4<=DAY(EOMONTH(DATE(Einstellungen!$B$3,3,1),0)),DATE(Einstellungen!$B$3,3,4),""),"") -> 46085 | B8: =IF(A8="","",TEXT(A8,"TTT")) -> Mi | L8: =IF(A8="","",IFERROR(SUM(C8:K8),0)) -> 0
A9: =IFERROR(IF(5<=DAY(EOMONTH(DATE(Einstellungen!$B$3,3,1),0)),DATE(Einstellungen!$B$3,3,5),""),"") -> 46086 | B9: =IF(A9="","",TEXT(A9,"TTT")) -> Do | L9: =IF(A9="","",IFERROR(SUM(C9:K9),0)) -> 0
A10: =IFERROR(IF(6<=DAY(EOMONTH(DATE(Einstellungen!$B$3,3,1),0)),DATE(Einstellungen!$B$3,3,6),""),"") -> 46087 | B10: =IF(A10="","",TEXT(A10,"TTT")) -> Fr | L10: =IF(A10="","",IFERROR(SUM(C10:K10),0)) -> 0
A11: =IFERROR(IF(7<=DAY(EOMONTH(DATE(Einstellungen!$B$3,3,1),0)),DATE(Einstellungen!$B$3,3,7),""),"") -> 46088 | B11: =IF(A11="","",TEXT(A11,"TTT")) -> Sa | L11: =IF(A11="","",IFERROR(SUM(C11:K11),0)) -> 0
A12: =IFERROR(IF(8<=DAY(EOMONTH(DATE(Einstellungen!$B$3,3,1),0)),DATE(Einstellungen!$B$3,3,8),""),"") -> 46089 | B12: =IF(A12="","",TEXT(A12,"TTT")) -> So | L12: =IF(A12="","",IFERROR(SUM(C12:K12),0)) -> 0
A13: =IFERROR(IF(9<=DAY(EOMONTH(DATE(Einstellungen!$B$3,3,1),0)),DATE(Einstellungen!$B$3,3,9),""),"") -> 46090 | B13: =IF(A13="","",TEXT(A13,"TTT")) -> Mo | L13: =IF(A13="","",IFERROR(SUM(C13:K13),0)) -> 0
A14: =IFERROR(IF(10<=DAY(EOMONTH(DATE(Einstellungen!$B$3,3,1),0)),DATE(Einstellungen!$B$3,3,10),""),"") -> 46091 | B14: =IF(A14="","",TEXT(A14,"TTT")) -> Di | L14: =IF(A14="","",IFERROR(SUM(C14:K14),0)) -> 0
A15: =IFERROR(IF(11<=DAY(EOMONTH(DATE(Einstellungen!$B$3,3,1),0)),DATE(Einstellungen!$B$3,3,11),""),"") -> 46092 | B15: =IF(A15="","",TEXT(A15,"TTT")) -> Mi | L15: =IF(A15="","",IFERROR(SUM(C15:K15),0)) -> 0
A16: =IFERROR(IF(12<=DAY(EOMONTH(DATE(Einstellungen!$B$3,3,1),0)),DATE(Einstellungen!$B$3,3,12),""),"") -> 46093 | B16: =IF(A16="","",TEXT(A16,"TTT")) -> Do | L16: =IF(A16="","",IFERROR(SUM(C16:K16),0)) -> 0
A17: =IFERROR(IF(13<=DAY(EOMONTH(DATE(Einstellungen!$B$3,3,1),0)),DATE(Einstellungen!$B$3,3,13),""),"") -> 46094 | B17: =IF(A17="","",TEXT(A17,"TTT")) -> Fr | L17: =IF(A17="","",IFERROR(SUM(C17:K17),0)) -> 0
A18: =IFERROR(IF(14<=DAY(EOMONTH(DATE(Einstellungen!$B$3,3,1),0)),DATE(Einstellungen!$B$3,3,14),""),"") -> 46095 | B18: =IF(A18="","",TEXT(A18,"TTT")) -> Sa | L18: =IF(A18="","",IFERROR(SUM(C18:K18),0)) -> 0
A19: =IFERROR(IF(15<=DAY(EOMONTH(DATE(Einstellungen!$B$3,3,1),0)),DATE(Einstellungen!$B$3,3,15),""),"") -> 46096 | B19: =IF(A19="","",TEXT(A19,"TTT")) -> So | L19: =IF(A19="","",IFERROR(SUM(C19:K19),0)) -> 0
A20: =IFERROR(IF(16<=DAY(EOMONTH(DATE(Einstellungen!$B$3,3,1),0)),DATE(Einstellungen!$B$3,3,16),""),"") -> 46097 | B20: =IF(A20="","",TEXT(A20,"TTT")) -> Mo | L20: =IF(A20="","",IFERROR(SUM(C20:K20),0)) -> 0
A21: =IFERROR(IF(17<=DAY(EOMONTH(DATE(Einstellungen!$B$3,3,1),0)),DATE(Einstellungen!$B$3,3,17),""),"") -> 46098 | B21: =IF(A21="","",TEXT(A21,"TTT")) -> Di | L21: =IF(A21="","",IFERROR(SUM(C21:K21),0)) -> 0
A22: =IFERROR(IF(18<=DAY(EOMONTH(DATE(Einstellungen!$B$3,3,1),0)),DATE(Einstellungen!$B$3,3,18),""),"") -> 46099 | B22: =IF(A22="","",TEXT(A22,"TTT")) -> Mi | L22: =IF(A22="","",IFERROR(SUM(C22:K22),0)) -> 0
A23: =IFERROR(IF(19<=DAY(EOMONTH(DATE(Einstellungen!$B$3,3,1),0)),DATE(Einstellungen!$B$3,3,19),""),"") -> 46100 | B23: =IF(A23="","",TEXT(A23,"TTT")) -> Do | L23: =IF(A23="","",IFERROR(SUM(C23:K23),0)) -> 0
A24: =IFERROR(IF(20<=DAY(EOMONTH(DATE(Einstellungen!$B$3,3,1),0)),DATE(Einstellungen!$B$3,3,20),""),"") -> 46101 | B24: =IF(A24="","",TEXT(A24,"TTT")) -> Fr | L24: =IF(A24="","",IFERROR(SUM(C24:K24),0)) -> 0
A25: =IFERROR(IF(21<=DAY(EOMONTH(DATE(Einstellungen!$B$3,3,1),0)),DATE(Einstellungen!$B$3,3,21),""),"") -> 46102 | B25: =IF(A25="","",TEXT(A25,"TTT")) -> Sa | L25: =IF(A25="","",IFERROR(SUM(C25:K25),0)) -> 0
A26: =IFERROR(IF(22<=DAY(EOMONTH(DATE(Einstellungen!$B$3,3,1),0)),DATE(Einstellungen!$B$3,3,22),""),"") -> 46103 | B26: =IF(A26="","",TEXT(A26,"TTT")) -> So | L26: =IF(A26="","",IFERROR(SUM(C26:K26),0)) -> 0
A27: =IFERROR(IF(23<=DAY(EOMONTH(DATE(Einstellungen!$B$3,3,1),0)),DATE(Einstellungen!$B$3,3,23),""),"") -> 46104 | B27: =IF(A27="","",TEXT(A27,"TTT")) -> Mo | L27: =IF(A27="","",IFERROR(SUM(C27:K27),0)) -> 0
A28: =IFERROR(IF(24<=DAY(EOMONTH(DATE(Einstellungen!$B$3,3,1),0)),DATE(Einstellungen!$B$3,3,24),""),"") -> 46105 | B28: =IF(A28="","",TEXT(A28,"TTT")) -> Di | L28: =IF(A28="","",IFERROR(SUM(C28:K28),0)) -> 0
A29: =IFERROR(IF(25<=DAY(EOMONTH(DATE(Einstellungen!$B$3,3,1),0)),DATE(Einstellungen!$B$3,3,25),""),"") -> 46106 | B29: =IF(A29="","",TEXT(A29,"TTT")) -> Mi | L29: =IF(A29="","",IFERROR(SUM(C29:K29),0)) -> 0
A30: =IFERROR(IF(26<=DAY(EOMONTH(DATE(Einstellungen!$B$3,3,1),0)),DATE(Einstellungen!$B$3,3,26),""),"") -> 46107 | B30: =IF(A30="","",TEXT(A30,"TTT")) -> Do | L30: =IF(A30="","",IFERROR(SUM(C30:K30),0)) -> 0
A31: =IFERROR(IF(27<=DAY(EOMONTH(DATE(Einstellungen!$B$3,3,1),0)),DATE(Einstellungen!$B$3,3,27),""),"") -> 46108 | B31: =IF(A31="","",TEXT(A31,"TTT")) -> Fr | L31: =IF(A31="","",IFERROR(SUM(C31:K31),0)) -> 0
A32: =IFERROR(IF(28<=DAY(EOMONTH(DATE(Einstellungen!$B$3,3,1),0)),DATE(Einstellungen!$B$3,3,28),""),"") -> 46109 | B32: =IF(A32="","",TEXT(A32,"TTT")) -> Sa | L32: =IF(A32="","",IFERROR(SUM(C32:K32),0)) -> 0
A33: =IFERROR(IF(29<=DAY(EOMONTH(DATE(Einstellungen!$B$3,3,1),0)),DATE(Einstellungen!$B$3,3,29),""),"") -> 46110 | B33: =IF(A33="","",TEXT(A33,"TTT")) -> So | L33: =IF(A33="","",IFERROR(SUM(C33:K33),0)) -> 0
A34: =IFERROR(IF(30<=DAY(EOMONTH(DATE(Einstellungen!$B$3,3,1),0)),DATE(Einstellungen!$B$3,3,30),""),"") -> 46111 | B34: =IF(A34="","",TEXT(A34,"TTT")) -> Mo | L34: =IF(A34="","",IFERROR(SUM(C34:K34),0)) -> 0
A35: =IFERROR(IF(31<=DAY(EOMONTH(DATE(Einstellungen!$B$3,3,1),0)),DATE(Einstellungen!$B$3,3,31),""),"") -> 46112 | B35: =IF(A35="","",TEXT(A35,"TTT")) -> Di | L35: =IF(A35="","",IFERROR(SUM(C35:K35),0)) -> 0
A37: MONATSSUMME | C37: =SUM(C5:C35) -> 0 | D37: =SUM(D5:D35) -> 0 | E37: =SUM(E5:E35) -> 0 | F37: =SUM(F5:F35) -> 0 | G37: =SUM(G5:G35) -> 0 | H37: =SUM(H5:H35) -> 0 | I37: =SUM(I5:I35) -> 0 | J37: =SUM(J5:J35) -> 0 | K37: =SUM(K5:K35) -> 0 | L37: =SUM(C37:K37) -> 0
A40: ▶ DETAIL-LOG – Einzelbuchungen mit Kategorie & Beschreibung
A41: Datum | B41: Kategorie | C41: Unterkategorie | D41: Beschreibung | E41: Betrag
A93: GESAMT DETAIL-LOG | E93: =SUM(E42:E91) -> 0

Sheet April
A1: ="April " & TEXT(Einstellungen!$B$3,"0") -> April 2026
A3: ▶ SCHNELLEINGABE – Tagesausgaben nach Kategorie
A4: Datum | B4: Tag | C4: Wohnen | D4: Lebensmittel | E4: Transport | F4: Freizeit | G4: Gesundheit | H4: Kleidung | I4: Restaurant | J4: Versicherungen | K4: Sparen | L4: Gesamt | M4: Notiz
A5: =IFERROR(IF(1<=DAY(EOMONTH(DATE(Einstellungen!$B$3,4,1),0)),DATE(Einstellungen!$B$3,4,1),""),"") -> 46113 | B5: =IF(A5="","",TEXT(A5,"TTT")) -> Mi | L5: =IF(A5="","",IFERROR(SUM(C5:K5),0)) -> 0
A6: =IFERROR(IF(2<=DAY(EOMONTH(DATE(Einstellungen!$B$3,4,1),0)),DATE(Einstellungen!$B$3,4,2),""),"") -> 46114 | B6: =IF(A6="","",TEXT(A6,"TTT")) -> Do | L6: =IF(A6="","",IFERROR(SUM(C6:K6),0)) -> 0
A7: =IFERROR(IF(3<=DAY(EOMONTH(DATE(Einstellungen!$B$3,4,1),0)),DATE(Einstellungen!$B$3,4,3),""),"") -> 46115 | B7: =IF(A7="","",TEXT(A7,"TTT")) -> Fr | L7: =IF(A7="","",IFERROR(SUM(C7:K7),0)) -> 0
A8: =IFERROR(IF(4<=DAY(EOMONTH(DATE(Einstellungen!$B$3,4,1),0)),DATE(Einstellungen!$B$3,4,4),""),"") -> 46116 | B8: =IF(A8="","",TEXT(A8,"TTT")) -> Sa | L8: =IF(A8="","",IFERROR(SUM(C8:K8),0)) -> 0
A9: =IFERROR(IF(5<=DAY(EOMONTH(DATE(Einstellungen!$B$3,4,1),0)),DATE(Einstellungen!$B$3,4,5),""),"") -> 46117 | B9: =IF(A9="","",TEXT(A9,"TTT")) -> So | L9: =IF(A9="","",IFERROR(SUM(C9:K9),0)) -> 0
A10: =IFERROR(IF(6<=DAY(EOMONTH(DATE(Einstellungen!$B$3,4,1),0)),DATE(Einstellungen!$B$3,4,6),""),"") -> 46118 | B10: =IF(A10="","",TEXT(A10,"TTT")) -> Mo | L10: =IF(A10="","",IFERROR(SUM(C10:K10),0)) -> 0
A11: =IFERROR(IF(7<=DAY(EOMONTH(DATE(Einstellungen!$B$3,4,1),0)),DATE(Einstellungen!$B$3,4,7),""),"") -> 46119 | B11: =IF(A11="","",TEXT(A11,"TTT")) -> Di | L11: =IF(A11="","",IFERROR(SUM(C11:K11),0)) -> 0
A12: =IFERROR(IF(8<=DAY(EOMONTH(DATE(Einstellungen!$B$3,4,1),0)),DATE(Einstellungen!$B$3,4,8),""),"") -> 46120 | B12: =IF(A12="","",TEXT(A12,"TTT")) -> Mi | L12: =IF(A12="","",IFERROR(SUM(C12:K12),0)) -> 0
A13: =IFERROR(IF(9<=DAY(EOMONTH(DATE(Einstellungen!$B$3,4,1),0)),DATE(Einstellungen!$B$3,4,9),""),"") -> 46121 | B13: =IF(A13="","",TEXT(A13,"TTT")) -> Do | L13: =IF(A13="","",IFERROR(SUM(C13:K13),0)) -> 0
A14: =IFERROR(IF(10<=DAY(EOMONTH(DATE(Einstellungen!$B$3,4,1),0)),DATE(Einstellungen!$B$3,4,10),""),"") -> 46122 | B14: =IF(A14="","",TEXT(A14,"TTT")) -> Fr | L14: =IF(A14="","",IFERROR(SUM(C14:K14),0)) -> 0
A15: =IFERROR(IF(11<=DAY(EOMONTH(DATE(Einstellungen!$B$3,4,1),0)),DATE(Einstellungen!$B$3,4,11),""),"") -> 46123 | B15: =IF(A15="","",TEXT(A15,"TTT")) -> Sa | L15: =IF(A15="","",IFERROR(SUM(C15:K15),0)) -> 0
A16: =IFERROR(IF(12<=DAY(EOMONTH(DATE(Einstellungen!$B$3,4,1),0)),DATE(Einstellungen!$B$3,4,12),""),"") -> 46124 | B16: =IF(A16="","",TEXT(A16,"TTT")) -> So | L16: =IF(A16="","",IFERROR(SUM(C16:K16),0)) -> 0
A17: =IFERROR(IF(13<=DAY(EOMONTH(DATE(Einstellungen!$B$3,4,1),0)),DATE(Einstellungen!$B$3,4,13),""),"") -> 46125 | B17: =IF(A17="","",TEXT(A17,"TTT")) -> Mo | L17: =IF(A17="","",IFERROR(SUM(C17:K17),0)) -> 0
A18: =IFERROR(IF(14<=DAY(EOMONTH(DATE(Einstellungen!$B$3,4,1),0)),DATE(Einstellungen!$B$3,4,14),""),"") -> 46126 | B18: =IF(A18="","",TEXT(A18,"TTT")) -> Di | L18: =IF(A18="","",IFERROR(SUM(C18:K18),0)) -> 0
A19: =IFERROR(IF(15<=DAY(EOMONTH(DATE(Einstellungen!$B$3,4,1),0)),DATE(Einstellungen!$B$3,4,15),""),"") -> 46127 | B19: =IF(A19="","",TEXT(A19,"TTT")) -> Mi | L19: =IF(A19="","",IFERROR(SUM(C19:K19),0)) -> 0
A20: =IFERROR(IF(16<=DAY(EOMONTH(DATE(Einstellungen!$B$3,4,1),0)),DATE(Einstellungen!$B$3,4,16),""),"") -> 46128 | B20: =IF(A20="","",TEXT(A20,"TTT")) -> Do | L20: =IF(A20="","",IFERROR(SUM(C20:K20),0)) -> 0
